<?xml version="1.0" encoding="utf-8" ?>
<!-- =================================================================================== -->
<!-- |    This document was autogenerated by xacro from /home/taira/work/mer_lab-master/ros_ws/src/projects/table_rearrange/table_rearrange/desc/franka_camera_control.xacro | -->
<!-- |    EDITING THIS FILE BY HAND IS NOT RECOMMENDED                                 | -->
<!-- =================================================================================== -->
<!-- Franka robot with a camera attached -->
<robot name="panda_hand_camera">
    <!-- Gazebo control plugin -->
<!--    <gazebo>-->
<!--        <plugin filename="libgazebo_ros_control.so" name="gazebo_ros_control">-->
<!--            <robotNamespace>/panda</robotNamespace>-->
<!--            <robotSimType>gazebo_ros_control/DefaultRobotHWSim</robotSimType>-->
<!--        </plugin>-->
<!--    </gazebo>-->
    <gazebo>
        <plugin name="gazebo_ros_control" filename="libgazebo_ros_control.so">
            <robotNamespace>/</robotNamespace>
        </plugin>
    </gazebo>
    <link name="world"/>
    <joint name="fixed" type="fixed">
        <parent link="world"/>
        <child link="panda_link0"/>
    </joint>
    <link name="panda_link0">
        <visual>
            <geometry>
                <mesh filename="package://relaxed_ik/meshes/visual/link0.dae"/>
            </geometry>
        </visual>
        <collision>
            <geometry>
                <mesh filename="package://relaxed_ik/meshes/collision/link0.stl"/>
            </geometry>
        </collision>

        <inertial>
            <mass value="0.1"/>
            <inertia ixx="0.03" ixy="0.0" ixz="0.0" iyy="0.03" iyz="0.0" izz="0.03"/>
        </inertial>

    </link>
    <link name="panda_link1">
        <visual>
            <geometry>
                <mesh filename="package://relaxed_ik/meshes/visual/link1.dae"/>
            </geometry>
        </visual>
        <collision>
            <geometry>
                <mesh filename="package://relaxed_ik/meshes/collision/link1.stl"/>
            </geometry>
        </collision>

        <inertial>
            <mass value="0.1"/>
            <inertia ixx="0.03" ixy="0.0" ixz="0.0" iyy="0.03" iyz="0.0" izz="0.03"/>
        </inertial>

    </link>
    <joint name="panda_joint1" type="revolute">
        <safety_controller k_position="100.0" k_velocity="40.0" soft_lower_limit="-2.8973" soft_upper_limit="2.8973"/>
        <origin rpy="0 0 0" xyz="0 0 0.333"/>
        <parent link="panda_link0"/>
        <child link="panda_link1"/>
        <axis xyz="0 0 1"/>
        <limit effort="87" lower="-2.8973" upper="2.8973" velocity="2.1750"/>
    </joint>
    <link name="panda_link2">
        <visual>
            <geometry>
                <mesh filename="package://relaxed_ik/meshes/visual/link2.dae"/>
            </geometry>
        </visual>
        <collision>
            <geometry>
                <mesh filename="package://relaxed_ik/meshes/collision/link2.stl"/>
            </geometry>
        </collision>

        <inertial>
            <mass value="0.1"/>
            <inertia ixx="0.03" ixy="0.0" ixz="0.0" iyy="0.03" iyz="0.0" izz="0.03"/>
        </inertial>

    </link>
    <joint name="panda_joint2" type="revolute">
        <safety_controller k_position="100.0" k_velocity="40.0" soft_lower_limit="-1.7628" soft_upper_limit="1.7628"/>
        <origin rpy="-1.57079632679 0 0" xyz="0 0 0"/>
        <parent link="panda_link1"/>
        <child link="panda_link2"/>
        <axis xyz="0 0 1"/>
        <limit effort="87" lower="-1.7628" upper="1.7628" velocity="2.1750"/>
    </joint>
    <link name="panda_link3">
        <visual>
            <geometry>
                <mesh filename="package://relaxed_ik/meshes/visual/link3.dae"/>
            </geometry>
        </visual>
        <collision>
            <geometry>
                <mesh filename="package://relaxed_ik/meshes/collision/link3.stl"/>
            </geometry>
        </collision>

        <inertial>
            <mass value="0.1"/>
            <inertia ixx="0.03" ixy="0.0" ixz="0.0" iyy="0.03" iyz="0.0" izz="0.03"/>
        </inertial>

    </link>
    <joint name="panda_joint3" type="revolute">
        <safety_controller k_position="100.0" k_velocity="40.0" soft_lower_limit="-2.8973" soft_upper_limit="2.8973"/>
        <origin rpy="1.57079632679 0 0" xyz="0 -0.316 0"/>
        <parent link="panda_link2"/>
        <child link="panda_link3"/>
        <axis xyz="0 0 1"/>
        <limit effort="87" lower="-2.8973" upper="2.8973" velocity="2.1750"/>
    </joint>
    <link name="panda_link4">
        <visual>
            <geometry>
                <mesh filename="package://relaxed_ik/meshes/visual/link4.dae"/>
            </geometry>
        </visual>
        <collision>
            <geometry>
                <mesh filename="package://relaxed_ik/meshes/collision/link4.stl"/>
            </geometry>
        </collision>

        <inertial>
            <mass value="0.1"/>
            <inertia ixx="0.03" ixy="0.0" ixz="0.0" iyy="0.03" iyz="0.0" izz="0.03"/>
        </inertial>

    </link>
    <joint name="panda_joint4" type="revolute">
        <safety_controller k_position="100.0" k_velocity="40.0" soft_lower_limit="-3.0718" soft_upper_limit="-0.0698"/>
        <origin rpy="1.57079632679 0 0" xyz="0.0825 0 0"/>
        <parent link="panda_link3"/>
        <child link="panda_link4"/>
        <axis xyz="0 0 1"/>
        <limit effort="87" lower="-3.0718" upper="-0.0698" velocity="2.1750"/>
    </joint>
    <link name="panda_link5">
        <visual>
            <geometry>
                <mesh filename="package://relaxed_ik/meshes/visual/link5.dae"/>
            </geometry>
        </visual>
        <collision>
            <geometry>
                <mesh filename="package://relaxed_ik/meshes/collision/link5.stl"/>
            </geometry>
        </collision>

        <inertial>
            <mass value="0.1"/>
            <inertia ixx="0.03" ixy="0.0" ixz="0.0" iyy="0.03" iyz="0.0" izz="0.03"/>
        </inertial>

    </link>
    <joint name="panda_joint5" type="revolute">
        <safety_controller k_position="100.0" k_velocity="40.0" soft_lower_limit="-2.8973" soft_upper_limit="2.8973"/>
        <origin rpy="-1.57079632679 0 0" xyz="-0.0825 0.384 0"/>
        <parent link="panda_link4"/>
        <child link="panda_link5"/>
        <axis xyz="0 0 1"/>
        <limit effort="12" lower="-2.8973" upper="2.8973" velocity="2.6100"/>
    </joint>
    <link name="panda_link6">
        <visual>
            <geometry>
                <mesh filename="package://relaxed_ik/meshes/visual/link6.dae"/>
            </geometry>
        </visual>
        <collision>
            <geometry>
                <mesh filename="package://relaxed_ik/meshes/collision/link6.stl"/>
            </geometry>
        </collision>

        <inertial>
            <mass value="0.1"/>
            <inertia ixx="0.03" ixy="0.0" ixz="0.0" iyy="0.03" iyz="0.0" izz="0.03"/>
        </inertial>

    </link>
    <joint name="panda_joint6" type="revolute">
        <safety_controller k_position="100.0" k_velocity="40.0" soft_lower_limit="-0.0175" soft_upper_limit="3.7525"/>
        <origin rpy="1.57079632679 0 0" xyz="0 0 0"/>
        <parent link="panda_link5"/>
        <child link="panda_link6"/>
        <axis xyz="0 0 1"/>
        <limit effort="12" lower="-0.0175" upper="3.7525" velocity="2.6100"/>
    </joint>
    <!-- <link name="panda_link7">
        <visual>
            <geometry>
                <mesh filename="package://franka_description/meshes/visual/link7.dae"/>
            </geometry>
        </visual>
        <collision>
            <geometry>
                <mesh filename="package://franka_description/meshes/collision/link7.stl"/>
            </geometry>
        </collision>

        <inertial>
            <mass value="0.1"/>
            <inertia ixx="0.03" ixy="0.0" ixz="0.0" iyy="0.03" iyz="0.0" izz="0.03"/>
        </inertial>

    </link> -->
    <!-- <joint name="panda_joint7" type="revolute">
        <safety_controller k_position="100.0" k_velocity="40.0" soft_lower_limit="-2.8973" soft_upper_limit="2.8973"/>
        <origin rpy="1.57079632679 0 0" xyz="0.088 0 0"/>
        <parent link="panda_link6"/>
        <child link="panda_link7"/>
        <axis xyz="0 0 1"/>
        <limit effort="12" lower="-2.8973" upper="2.8973" velocity="2.6100"/>
    </joint> -->
    <!-- <link name="panda_link8"/> -->
    
    <!-- <joint name="panda_joint8" type="fixed">
        <origin rpy="0 0 0" xyz="0 0 0"/>
        <parent link="panda_link6"/>
        <child link="panda_link8"/>
        <axis xyz="0 0 0"/>
    </joint> --> 
    
    
    <link name="end_sphere">
        <visual>
          <geometry>
            <sphere radius="0.07"/>
          </geometry>
          <material name="green">
                <color rgba="0 1 0 1"/>
          </material>
        </visual>
        <inertial>
            <mass value="0.000001"/>
            <inertia ixx="0.03" ixy="0.0" ixz="0.0" iyy="0.03" iyz="0.0" izz="0.03"/>
        </inertial>
      </link>
      <gazebo reference="end_sphere">
        <material>Gazebo/Green</material>
      </gazebo>
      <joint name="panda_hand_joint" type="fixed">
        <parent link="panda_link6"/>
        <child link="end_sphere"/>
        <origin rpy="0 0 0" xyz="0.1 -0.1 0"/>
    </joint>


    <!-- <gazebo reference="camera">
        <material>Gazebo/Red</material>
        <sensor type="camera" name="camera">
          <update_rate>30.0</update_rate>
          <camera name="head">
            <horizontal_fov>1.3962634</horizontal_fov>
            <image>
              <width>800</width>
              <height>800</height>
              <format>R8G8B8</format>
            </image>
            <clip>
              <near>0.02</near>
              <far>300</far>
            </clip>
            <noise>
              <type>gaussian</type>
              
              <mean>0.0</mean>
              <stddev>0.007</stddev>
            </noise>
          </camera>
          <plugin name="camera_controller" filename="libgazebo_ros_openni_kinect.so">
            <alwaysOn>true</alwaysOn>
            <updateRate>0.0</updateRate>
            <cameraName>/roboticArm/camera</cameraName>
            <imageTopicName>image_raw</imageTopicName>
            <cameraInfoTopicName>camera_info</cameraInfoTopicName>
            <frameName>camera</frameName>
            <hackBaseline>0.07</hackBaseline>
            <distortionK1>0.0</distortionK1>
            <distortionK2>0.0</distortionK2>
            <distortionK3>0.0</distortionK3>
            <distortionT1>0.0</distortionT1>
            <distortionT2>0.0</distortionT2>
          </plugin>
        </sensor>
      </gazebo> -->
      <gazebo reference="camera_link">
      <sensor type="depth" name="camera_link">
        <always_on>1</always_on>
        <visualize>true</visualize>
        <update_rate>20</update_rate>
        <camera>
          <horizontal_fov>1.4397198</horizontal_fov>
          <image>
            <width>800</width>
            <height>800</height>
            <format>R8G8B8</format>  <!--Changed format since channels were inverted, to go back, change to R8G8B8-->
          </image>
          <clip>
            <near>0.02</near>
            <far>300</far>
          </clip>
          <noise>   <!-- This does apparently nothing neither RGB nor depth-->
            <type>gaussian</type>
            <mean>0.0</mean>
            <stddev>5.0</stddev>
        </noise>
        </camera>
    
        <plugin name="camera_controller" filename="libgazebo_ros_openni_kinect.so">
          <baseline>0.2</baseline>
          <alwaysOn>true</alwaysOn>
          <updateRate>120</updateRate>
          <cameraName>/camera_link</cameraName>
          <imageTopicName>/camera_link/rgb/image_raw</imageTopicName>
          <cameraInfoTopicName>/camera_link/rgb/camera_info</cameraInfoTopicName>
          <depthImageTopicName>/camera_link/depth/image_raw</depthImageTopicName>
          <depthImageInfoTopicName>/camera_link/depth/camera_info</depthImageInfoTopicName>
          <pointCloudTopicName>/camera_link/depth/points</pointCloudTopicName>
          <frameName>camera_link_optical</frameName>
          <pointCloudCutoff>0.5</pointCloudCutoff>
          <pointCloudCutoffMax>3</pointCloudCutoffMax>
          <distortionK1>0</distortionK1>
          <distortionK2>0</distortionK2>
          <distortionK3>0</distortionK3>
          <distortionT1>0</distortionT1>
          <distortionT2>0</distortionT2>
          <CxPrime>0</CxPrime>
          <Cx>0</Cx>
          <Cy>0</Cy>
          <focalLength>0</focalLength>
          <hackBaseline>0</hackBaseline>
        </plugin>
          </sensor>
        </gazebo>
    <link name="stand">
        <visual>
              <geometry>
                <box size="0.06 0.06 0.8"/>
              </geometry>
              <origin rpy="0 0 0" xyz="0 0 0.4"/>
              <material name="white"/>
            </visual>
            <inertial>
                <mass value="0.1"/>
                <inertia ixx="0.03" ixy="0.0" ixz="0.0" iyy="0.03" iyz="0.0" izz="0.03"/>
            </inertial>
        
      </link>
      <joint name="fixed_stand" type="fixed">
        <origin xyz="1.2 0 0" rpy="0 0 0"/>
            <parent link="world"/>
            <child link="stand"/>
      </joint>
      <link name="camera_link">
        <visual>
            <origin xyz="0 0 0" rpy="0 0 0"/>
             <geometry>
              <mesh filename="package://relaxed_ik/meshes/kinect/kinect.dae"/>
            
              <!-- <mesh scale="0.005 0.005 0.005" filename="package://vision_control/meshes/tripod/tripod.dae"/> -->
             </geometry>
           </visual>
             <collision>
             <origin xyz="0.0 0.0 0.0" rpy="0 0 0"/>
               <geometry>
                 <box size="0.1 0.1 0.1"/>
               </geometry>
             </collision>
           <inertial>
             <mass value="0.5" />
             <origin xyz="0 0 0" />
             <inertia ixx="0.003881243" ixy="0.0" ixz="0.0"
                      iyy="0.000498940" iyz="0.0"
                      izz="0.003879257" />
           </inertial>
        <!-- <visual>
            <geometry>
              <box size="0.1 0.1 0.1"/>
            </geometry>
            <origin rpy="0 0 0" xyz="0 0 0"/>
            <material name="red"/>
          </visual>
          <inertial>
              <mass value="0.1"/>
              <inertia ixx="0.03" ixy="0.0" ixz="0.0" iyy="0.03" iyz="0.0" izz="0.03"/>
          </inertial> -->
        </link>
        <link name="camera_link_optical"/>
        <joint name="camera_depth_optical_joint" type="fixed">
            <origin xyz="0 0 0.85" rpy="0 0 3.14"/>
                <parent link="camera_link"/>
                <child link="camera_link_optical"/>
          </joint>
      <joint name="fixed_camera" type="fixed">
        <origin xyz="-0.035 0 0.85" rpy="0 0 3.14"/>
            <parent link="stand"/>
            <child link="camera_link"/>
      </joint>
      <gazebo reference="stand">
        <material>Gazebo/Black</material>
      </gazebo>
      <gazebo reference="camera_link">
        <material>Gazebo/Gray</material>
      </gazebo>
      

    
    <transmission name="trans_panda_joint1">
        <type>transmission_interface/SimpleTransmission</type>
        <joint name="panda_joint1">
            <hardwareInterface>hardware_interface/EffortJointInterface</hardwareInterface>
        </joint>
        <actuator name="panda_joint1_motor">
            <hardwareInterface>hardware_interface/EffortJointInterface</hardwareInterface>
            <mechanicalReduction>1</mechanicalReduction>
        </actuator>
    </transmission>
    <transmission name="trans_panda_joint2">
        <type>transmission_interface/SimpleTransmission</type>
        <joint name="panda_joint2">
            <hardwareInterface>hardware_interface/EffortJointInterface</hardwareInterface>
        </joint>
        <actuator name="panda_joint2_motor">
            <hardwareInterface>hardware_interface/EffortJointInterface</hardwareInterface>
            <mechanicalReduction>1</mechanicalReduction>
        </actuator>
    </transmission>
    <transmission name="trans_panda_joint3">
        <type>transmission_interface/SimpleTransmission</type>
        <joint name="panda_joint3">
            <hardwareInterface>hardware_interface/EffortJointInterface</hardwareInterface>
        </joint>
        <actuator name="panda_joint3_motor">
            <hardwareInterface>hardware_interface/EffortJointInterface</hardwareInterface>
            <mechanicalReduction>1</mechanicalReduction>
        </actuator>
    </transmission>
    <transmission name="trans_panda_joint4">
        <type>transmission_interface/SimpleTransmission</type>
        <joint name="panda_joint4">
            <hardwareInterface>hardware_interface/EffortJointInterface</hardwareInterface>
        </joint>
        <actuator name="panda_joint4_motor">
            <hardwareInterface>hardware_interface/EffortJointInterface</hardwareInterface>
            <mechanicalReduction>1</mechanicalReduction>
        </actuator>
    </transmission>
    <transmission name="trans_panda_joint5">
        <type>transmission_interface/SimpleTransmission</type>
        <joint name="panda_joint5">
            <hardwareInterface>hardware_interface/EffortJointInterface</hardwareInterface>
        </joint>
        <actuator name="panda_joint5_motor">
            <hardwareInterface>hardware_interface/EffortJointInterface</hardwareInterface>
            <mechanicalReduction>1</mechanicalReduction>
        </actuator>
    </transmission>
    <transmission name="trans_panda_joint6">
        <type>transmission_interface/SimpleTransmission</type>
        <joint name="panda_joint6">
            <hardwareInterface>hardware_interface/EffortJointInterface</hardwareInterface>
        </joint>
        <actuator name="panda_joint6_motor">
            <hardwareInterface>hardware_interface/EffortJointInterface</hardwareInterface>
            <mechanicalReduction>1</mechanicalReduction>
        </actuator>
    </transmission>
    <!-- <transmission name="trans_panda_joint7">
        <type>transmission_interface/SimpleTransmission</type>
        <joint name="panda_joint7">
            <hardwareInterface>hardware_interface/EffortJointInterface</hardwareInterface>
        </joint>
        <actuator name="panda_joint7_motor">
            <hardwareInterface>hardware_interface/EffortJointInterface</hardwareInterface>
            <mechanicalReduction>1</mechanicalReduction>
        </actuator>
    </transmission> -->
    <!-- <transmission name="trans_panda_finger_joint1">
        <type>transmission_interface/SimpleTransmission</type>
        <joint name="panda_finger_joint1">
            <hardwareInterface>hardware_interface/EffortJointInterface</hardwareInterface>
        </joint>
        <actuator name="panda_finger_joint1_motor">
            <hardwareInterface>hardware_interface/EffortJointInterface</hardwareInterface>
            <mechanicalReduction>1</mechanicalReduction>
        </actuator>
    </transmission>
    <transmission name="trans_panda_finger_joint2">
        <type>transmission_interface/SimpleTransmission</type>
        <joint name="panda_finger_joint2">
            <hardwareInterface>hardware_interface/EffortJointInterface</hardwareInterface>
        </joint>
        <actuator name="panda_finger_joint2_motor">
            <hardwareInterface>hardware_interface/EffortJointInterface</hardwareInterface>
            <mechanicalReduction>1</mechanicalReduction>
        </actuator>
    </transmission> -->

</robot>
