<?xml version="1.0"?>
<robot name="block">
  <link name="world" />

  <link name="block">
    <visual>
      <geometry>
	<mesh filename="package://lock_key/mesh/block.STL" />
      </geometry>
    </visual>
    <collision>
      <geometry>
	<mesh filename="package://lock_key/mesh/block.STL" />
      </geometry>
    </collision>
    <!-- PLACEHOLDER VALUES -->
    <inertial>
      <mass value="100" />
      <inertia ixx="100" ixy="0" ixz="0"
	       iyy="100" iyz="0"
	       izz="100" />
    </inertial>
  </link>
  <gazebo reference = "block">
  <material> Gazebo/Black</material>
  </gazebo>
  <joint name="table_key" type="floating">
    <origin rpy="0 0 0" xyz="-0.1  0.15 0" />
    <parent link="world" />
    <child link="block" />
  </joint>

</robot>
