<?xml version="1.0"?>
<robot name="key">
  <link name="world" />

  <link name="key">
    <visual>
      <geometry>
	<mesh filename="package://lock_key/mesh/key.STL" />
      </geometry>
    </visual>
    <collision>
      <geometry>
	<mesh filename="package://lock_key/mesh/key.STL" />
      </geometry>
    </collision>
    <inertial>
      <mass value="0.1" />
      <inertia ixx="0.1" ixy="0.1" ixz="0.1"
	       iyy="0.1" iyz="0.1"
	       izz="0.1" />
    </inertial>
  </link>
  <gazebo reference = "key">
  <material> Gazebo/Blue</material>
  <dampingFactor>0.005</dampingFactor>
  <kp>1000000.0</kp>
  <kd>1.0</kd>
  <mu1>10000.0</mu1>
  <mu2>10000.0</mu2>
  <minDepth>0.001</minDepth>
  </gazebo>
  <joint name="table_key" type="floating">
    <origin rpy="1.57 1.57 1.57" xyz="0.007250 0.002750 0.030000" />
    <parent link="world" />
    <child link="key" />
  </joint>

</robot>
<!-- Inrtial Tensor of Key from Meshlab at a scale of 10^5 are
| 0.000145 -0.000000 -0.000000 |
| -0.000000 0.000152 0.000000 |
| -0.000000 0.000000 0.000010 | -->