<?xml version="1.0"?>
<robot name="key">
  <link name="world" />

  <link name="key">
    <visual>
      <geometry>
	<mesh filename="package://lock_key/mesh/key.STL" />
      </geometry>
      <!--Need to create my own mesh files-->
    </visual>
    <collision>
      <geometry>
	<mesh filename="package://lock_key/mesh/key.STL" />
      </geometry>
    </collision>
    <surface>
        <friction>
          <ode>
            <mu>0.7</mu>
            <mu2>0.7</mu2>
          </ode>
        </friction>
      </surface>
    <!-- PLACEHOLDER VALUES -->
    <inertial>
      <mass value="0.1" />
      <inertia ixx="0.1" ixy="0.1" ixz="0.1"
	       iyy="0.1" iyz="0.1"
	       izz="0.1" />
    </inertial>
  </link>
  <gazebo reference = "key">
  <material> Gazebo/Blue</material>
  </gazebo>
  <joint name="table_key" type="floating">
    <origin rpy="1.57 1.57 1.57" xyz="0.007250 0.002750 0.030000" />
    <parent link="world" />
    <child link="key" />
  </joint>

</robot>
<!-- Inrtial Tensor of Key from Meshlab at a scale of 10^5 are
| 0.000145 -0.000000 -0.000000 |
| -0.000000 0.000152 0.000000 |
| -0.000000 0.000000 0.000010 | -->