<?xml version="1.0"?>
<robot name="key">
  <link name="world" />

  <link name="key">
    <visual>
      <geometry>
	<!-- <mesh filename="package://lock_key/mesh/key.STL" /> -->
  <box size="0.0145 0.0055 0.06" />
      </geometry>
    </visual>
    <collision>
      <!-- <geometry>
	<mesh filename="package://lock_key/mesh/key.STL" />
      </geometry> -->
      <geometry>
          <box size="0.0145 0.0055 0.06" />
        </geometry>
    <surface>
    
    <friction>
      <torsional>
        <coefficient>10000.0</coefficient>
        <mu1>10000.0</mu1>
        <mu2>10000.0</mu2>
        <use_patch_radius>true</use_patch_radius>
        <patch_radius>1.0</patch_radius>
      </torsional>
    </friction>
    
    <contact>
      <poissons_ratio>0.5</poissons_ratio>
      <elastic_modulus>1e8</elastic_modulus>
    </contact>
    
    <max_contacts>100</max_contacts>
    </surface>
    </collision>
    <inertial>
      <mass value="0.1" />
      <inertia ixx="0.001" ixy="0.0" ixz="0.0"
	       iyy="0.001" iyz="0.0"
	       izz="0.001" />
    </inertial>
  </link>

  <gazebo reference = "key">
  <material> Gazebo/Blue</material>
  <dampingFactor>0.005</dampingFactor>
  <kp>100000000.0</kp>
  <kd>1.0</kd>
  <mu1>100000.0</mu1>
  <mu2>100000.0</mu2>
  <maxVel>1.0</maxVel>
  <minDepth>10</minDepth>
<turnGravityOff>true</turnGravityOff>
  </gazebo>

  <joint name="table_key" type="floating">
    <origin rpy="0.0 0. 0.0" xyz="0.0 0.0 0.0" />
    <parent link="world" />
    <child link="key" />
  </joint>

</robot>
<!-- Inertial Tensor of Key from Meshlab at a scale of 10^5 are
| 0.000145 -0.000000 -0.000000 |
| -0.000000 0.000152 0.000000 |
| -0.000000 0.000000 0.000010 | -->
