<?xml version="1.0"?>
<robot name="mug">
  <link name="world" />

  <link name="mug">
    <visual>
      <geometry>
	<mesh filename="package://ycb_models/mesh/mug.dae" />
      </geometry>
    </visual>
    <collision>
      <geometry>
	<mesh filename="package://ycb_models/mesh/mug.dae" />
      </geometry>
    </collision>
    <!-- PLACEHOLDER VALUES -->
    <inertial>
      <origin xyz="-0.0188777 0.0268737 -0.016566" rpy="0 0 0" />
      <mass value="1" />
      <inertia ixx="8.6015056998e-04" ixy="-2.4394589683e-05" ixz="-5.4461180345e-06"
	       iyy="1.2467452473e-03" iyz="2.1380083871e-05"
	       izz="9.7719543273e-04" />
    </inertial>
  </link>

  <joint name="table_mug" type="floating">
    <origin rpy="0 0 0" xyz="0 0 0" />
    <parent link="world" />
    <child link="mug" />
  </joint>

</robot>
