<?xml version="1.0" encoding="utf-8"?>
<robot xmlns:xacro="http://www.ros.org/wiki/xacro" name="hand">
  <xacro:macro name="hand" params="connected_to:='' ns:='' rpy:='0 0 0' xyz:='0 0 0' ">
    <xacro:unless value="${connected_to == ''}">
      <joint name="${ns}_hand_joint" type="fixed">
        <parent link="${connected_to}"/>
        <child link="${ns}_hand"/>
        <origin xyz="${xyz}" rpy="${rpy}"/>
      </joint>
    </xacro:unless>
    <link name="${ns}_hand">
      <visual>
        <geometry>
          <mesh filename="package://franka_description/meshes/visual/hand.dae"/>
        </geometry>
      </visual>
      <visual>
        <origin xyz="0.03 0.0 0.07" rpy="-${pi/2} -${pi/2} -${pi/2}"/>
        <geometry>
          <mesh filename="package://active_vision/models/kinectAV/meshes/realsense.stl"/>
        </geometry>
      </visual>
      <visual>
        <origin xyz="0.018 0.0 0.007" rpy="0 0 0"/>
        <geometry>
          <mesh filename="package://active_vision/models/kinectAV/meshes/panda_realsenseD435_mount.stl"/>
        </geometry>
      </visual>
      <collision>
        <geometry>
          <mesh filename="package://franka_description/meshes/collision/hand.stl"/>
        </geometry>
      </collision>
	    <inertial>
        <mass value="0.1" />
        <inertia ixx="0.03" iyy="0.03" izz="0.03" ixy="0.0" ixz="0.0" iyz="0.0" />
      </inertial>
    </link>
    <link name="${ns}_leftfinger">
      <visual>
        <geometry>
          <mesh filename="package://franka_description/meshes/visual/finger.dae"/>
        </geometry>
      </visual>
      <collision>
        <geometry>
          <mesh filename="package://franka_description/meshes/collision/finger.stl"/>
        </geometry>
      </collision>
	    <inertial>
        <mass value="0.1" />
        <inertia ixx="0.03" iyy="0.03" izz="0.03" ixy="0.0" ixz="0.0" iyz="0.0" />
      </inertial>
    </link>
    <link name="${ns}_rightfinger">
      <visual>
        <origin xyz="0 0 0" rpy="0 0 ${pi}"/>
        <geometry>
          <mesh filename="package://franka_description/meshes/visual/finger.dae"/>
        </geometry>
      </visual>
      <collision>
        <origin xyz="0 0 0" rpy="0 0 ${pi}"/>
        <geometry>
          <mesh filename="package://franka_description/meshes/collision/finger.stl"/>
        </geometry>
      </collision>
	    <inertial>
        <mass value="0.1" />
        <inertia ixx="0.03" iyy="0.03" izz="0.03" ixy="0.0" ixz="0.0" iyz="0.0" />
      </inertial>
    </link>

  <gazebo reference="panda_leftfinger">
    <kp>1000000.0</kp>
    <kd>1.0</kd>
    <mu1>100000.0</mu1>
    <mu2>100000.0</mu2>
    <minDepth>0.001</minDepth>
    <maxVel>0.001</maxVel>
  </gazebo>
  <gazebo reference="panda_rightfinger">
    <kp>1000000.0</kp>
    <kd>1.0</kd>
    <mu1>100000.0</mu1>
    <mu2>100000.0</mu2>
    <minDepth>0.001</minDepth>
    <maxVel>0.001</maxVel>
  </gazebo>

  <gazebo>
   <plugin name="gazebo_grasp_fix" filename="libgazebo_grasp_fix.so">
      <arm>
         <arm_name>${connected_to}</arm_name>
         <palm_link> ${ns}_link7  </palm_link>
         <gripper_link> panda_leftfinger </gripper_link>
         <gripper_link> panda_rightfinger </gripper_link>
         <!-- <gripper_link> ${ns}_link7 </gripper_link> -->
      </arm>
     <forces_angle_tolerance>100</forces_angle_tolerance>
     <update_rate>8</update_rate>
     <grip_count_threshold>8</grip_count_threshold>
     <max_grip_count>16</max_grip_count>
     <release_tolerance>0.001</release_tolerance>
     <disable_collisions_on_attach>false</disable_collisions_on_attach>
     <contact_topic>__default_topic__</contact_topic>
    </plugin>
  </gazebo>

  <joint name="${ns}_finger_joint1" type="prismatic">
    <parent link="${ns}_hand"/>
    <child link="${ns}_leftfinger"/>
    <origin xyz="0 0 0.0584" rpy="0 0 0"/>
    <axis xyz="0 1 0"/>
    <limit effort="1000" lower="0.0" upper="0.04" velocity="0.1"/>
  </joint>
  <joint name="${ns}_finger_joint2" type="prismatic">
    <parent link="${ns}_hand"/>
    <child link="${ns}_rightfinger"/>
    <origin xyz="0 0 0.0584" rpy="0 0 0"/>
    <axis xyz="0 -1 0"/>
    <limit effort="1000" lower="0.0" upper="0.04" velocity="0.1"/>
    <mimic joint="${ns}_finger_joint1" />
  </joint>

  <transmission name="f_t_1">
    <type>transmission_interface/SimpleTransmission</type>
    <joint name="${ns}_finger_joint1">
      <hardwareInterface>hardware_interface/EffortJointInterface</hardwareInterface>
    </joint>
    <actuator name="motor_finger_1">
    	<hardwareInterface>hardware_interface/EffortJointInterface</hardwareInterface>
    	<mechanicalReduction>1</mechanicalReduction>
    </actuator>
  </transmission>
  <transmission name="f_t_2">
    <type>transmission_interface/SimpleTransmission</type>
    <joint name="${ns}_finger_joint2">
      <hardwareInterface>hardware_interface/EffortJointInterface</hardwareInterface>
    </joint>
    <actuator name="motor_finger_2">
    	<hardwareInterface>hardware_interface/EffortJointInterface</hardwareInterface>
    	<mechanicalReduction>1</mechanicalReduction>
    </actuator>
  </transmission>

  </xacro:macro>
</robot>
