<?xml version='1.0' encoding='utf-8'?>
<robot xmlns:xacro="http://www.ros.org/wiki/xacro" name="panda">
  <!-- <xacro:macro name="updated_panda_arm" params="arm_id:='panda' description_pkg:='franka_description' connected_to:='' xyz:='0 0 0' rpy:='0 0 0'"> -->



    <!-- <xacro:unless value="${not connected_to}">
      <joint name="panda_joint_${connected_to}" type="fixed">
        <parent link="${connected_to}"/>
        <child link="panda_link0"/>
        <origin rpy="${rpy}" xyz="${xyz}"/>
      </joint>
    </xacro:unless> -->

    <link name="world"/>

    <joint name="fixed" type="fixed">
      <parent link="world"/>
      <child link="panda_link0"/>
    </joint>

    <link name="panda_link0">
      <visual>
        <geometry>
          <mesh filename="package://franka_description/meshes/visual/link0.dae"/>
        </geometry>
      </visual>
      <collision>
        <geometry>
          <mesh filename="package://franka_description/meshes/collision/link0.stl"/>
        </geometry>
      </collision>
      <inertial>
        <mass value="3.06357" />
        <inertia ixx="0.03" iyy="0.03" izz="0.03" ixy="0.0" ixz="0.0" iyz="0.0" />
      </inertial>
    </link>

    <link name="panda_link1">
      <visual>
        <geometry>
          <mesh filename="package://franka_description/meshes/visual/link1.dae"/>
        </geometry>
      </visual>
      <collision>
        <geometry>
          <mesh filename="package://franka_description/meshes/collision/link1.stl"/>
        </geometry>
      </collision>
      <inertial>
        <mass value="2.34471" />
        <inertia ixx="0.03" iyy="0.03" izz="0.03" ixy="0.0" ixz="0.0" iyz="0.0" />
      </inertial>
    </link>

    <joint name="panda_joint1" type="revolute">
      <safety_controller k_position="100.0" k_velocity="40.0" soft_lower_limit="-2.8973" soft_upper_limit="2.8973"/>
      <origin rpy="0 0 0" xyz="0 0 0.333"/>
      <parent link="panda_link0"/>
      <child link="panda_link1"/>
      <axis xyz="0 0 1"/>
      <limit effort="87" lower="-2.8973" upper="2.8973" velocity="2.1750"/>
    </joint>

    <link name="panda_link2">
      <visual>
        <geometry>
          <mesh filename="package://franka_description/meshes/visual/link2.dae"/>
        </geometry>
      </visual>
      <collision>
        <geometry>
          <mesh filename="package://franka_description/meshes/collision/link2.stl"/>
        </geometry>
      </collision>
      <inertial>
        <mass value="2.36414" />
        <inertia ixx="0.03" iyy="0.03" izz="0.03" ixy="0.0" ixz="0.0" iyz="0.0" />
      </inertial>
    </link>

    <joint name="panda_joint2" type="revolute">
      <safety_controller k_position="100.0" k_velocity="40.0" soft_lower_limit="-1.7628" soft_upper_limit="1.7628"/>
      <origin rpy="-1.570 0 0" xyz="0 0 0"/>
      <parent link="panda_link1"/>
      <child link="panda_link2"/>
      <axis xyz="0 0 1"/>
      <limit effort="87" lower="-1.7628" upper="1.7628" velocity="2.1750"/>
    </joint>

    <link name="panda_link3">
      <visual>
        <geometry>
          <mesh filename="package://franka_description/meshes/visual/link3.dae"/>
        </geometry>
      </visual>
      <collision>
        <geometry>
          <mesh filename="package://franka_description/meshes/collision/link3.stl"/>
        </geometry>
      </collision>
      <inertial>
        <mass value="2.38050" />
        <inertia ixx="0.03" iyy="0.03" izz="0.03" ixy="0.0" ixz="0.0" iyz="0.0" />
      </inertial>
    </link>

    <joint name="panda_joint3" type="revolute">
      <safety_controller k_position="100.0" k_velocity="40.0" soft_lower_limit="-2.8973" soft_upper_limit="2.8973"/>
      <origin rpy="1.570 0 0" xyz="0 -0.316 0"/>
      <parent link="panda_link2"/>
      <child link="panda_link3"/>
      <axis xyz="0 0 1"/>
      <limit effort="87" lower="-2.8973" upper="2.8973" velocity="2.1750"/>
    </joint>

    <link name="panda_link4">
      <visual>
        <geometry>
          <mesh filename="package://franka_description/meshes/visual/link4.dae"/>
        </geometry>
      </visual>
      <collision>
        <geometry>
          <mesh filename="package://franka_description/meshes/collision/link4.stl"/>
        </geometry>
      </collision>
      <inertial>
        <mass value="2.42754" />
        <inertia ixx="0.03" iyy="0.03" izz="0.03" ixy="0.0" ixz="0.0" iyz="0.0" />
      </inertial>
    </link>

    <joint name="panda_joint4" type="revolute">
      <safety_controller k_position="100.0" k_velocity="40.0" soft_lower_limit="-3.0718" soft_upper_limit="-0.0698"/>
      <origin rpy="1.570 0 0" xyz="0.0825 0 0"/>
      <parent link="panda_link3"/>
      <child link="panda_link4"/>
      <axis xyz="0 0 1"/>
      <limit effort="87" lower="-3.0718" upper="-0.0698" velocity="2.1750"/>
    </joint>

    <link name="panda_link5">
      <visual>
        <geometry>
          <mesh filename="package://franka_description/meshes/visual/link5.dae"/>
        </geometry>
      </visual>
      <collision>
        <geometry>
          <mesh filename="package://franka_description/meshes/collision/link5.stl"/>
        </geometry>
      </collision>
      <inertial>
        <mass value="3.49611" />
        <inertia ixx="0.03" iyy="0.03" izz="0.03" ixy="0.0" ixz="0.0" iyz="0.0" />
      </inertial>
    </link>

    <joint name="panda_joint5" type="revolute">
      <safety_controller k_position="100.0" k_velocity="40.0" soft_lower_limit="-2.8973" soft_upper_limit="2.8973"/>
      <origin rpy="-1.570 0 0" xyz="-0.0825 0.384 0"/>
      <parent link="panda_link4"/>
      <child link="panda_link5"/>
      <axis xyz="0 0 1"/>
      <limit effort="12" lower="-2.8973" upper="2.8973" velocity="2.6100"/>
    </joint>

    <link name="panda_link6">
      <visual>
        <geometry>
          <mesh filename="package://franka_description/meshes/visual/link6.dae"/>
        </geometry>
      </visual>
      <collision>
        <geometry>
          <mesh filename="package://franka_description/meshes/collision/link6.stl"/>
        </geometry>
      </collision>
      <inertial>
        <mass value="1.46736" />
        <inertia ixx="0.03" iyy="0.03" izz="0.03" ixy="0.0" ixz="0.0" iyz="0.0" />
      </inertial>
    </link>

    <joint name="panda_joint6" type="revolute">
      <safety_controller k_position="100.0" k_velocity="40.0" soft_lower_limit="-0.0175" soft_upper_limit="3.7525"/>
      <origin rpy="1.570 0 0" xyz="0 0 0"/>
      <parent link="panda_link5"/>
      <child link="panda_link6"/>
      <axis xyz="0 0 1"/>
      <limit effort="12" lower="-0.0175" upper="3.7525" velocity="2.6100"/>
    </joint>

    <link name="panda_link7">
      <visual>
        <geometry>
          <mesh filename="package://franka_description/meshes/visual/link7.dae"/>
        </geometry>
      </visual>
      <collision>
        <geometry>
          <mesh filename="package://franka_description/meshes/collision/link7.stl"/>
        </geometry>
      </collision>
      <inertial>
        <mass value="0.45606" />
        <inertia ixx="0.03" iyy="0.03" izz="0.03" ixy="0.0" ixz="0.0" iyz="0.0" />
      </inertial>
    </link>

    <joint name="panda_joint7" type="revolute">
      <safety_controller k_position="100.0" k_velocity="40.0" soft_lower_limit="-2.8973" soft_upper_limit="2.8973"/>
      <origin rpy="1.570 0 0" xyz="0.088 0 0"/>
      <parent link="panda_link6"/>
      <child link="panda_link7"/>
      <axis xyz="0 0 1"/>
      <limit effort="12" lower="-2.8973" upper="2.8973" velocity="2.6100"/>
    </joint>

    <link name="panda_link8"/>

    <joint name="panda_joint8" type="fixed">
      <origin rpy="0 0 0" xyz="0 0 0.107"/>
      <parent link="panda_link7"/>
      <child link="panda_link8"/>
      <axis xyz="0 0 0"/>
    </joint>
    <!-- putting gripper things -->
    <!-- ************************ -->
    <!-- <?xml version="1.0" encoding="utf-8"?>
<robot xmlns:xacro="http://www.ros.org/wiki/xacro" name="hand">
  <xacro:macro name="hand" params="connected_to:='' ns:='' rpy:='0 0 0' xyz:='0 0 0' "> -->
    <!-- <xacro:unless value="${connected_to == ''}"> -->
      <joint name="panda_hand_joint" type="fixed">
        <parent link="panda_link8"/>
        <child link="panda_hand"/>
        <origin xyz="0 0 0 " rpy="0 0 0"/>
      </joint>
    <!-- </xacro:unless> -->
    <link name="panda_hand">
      <visual>
        <geometry>
          <mesh filename="package://franka_description/meshes/visual/hand.dae"/>
        </geometry>
      </visual>
      <collision>
        <geometry>
          <mesh filename="package://franka_description/meshes/collision/hand.stl"/>
        </geometry>
      </collision>
	<inertial>
            <mass value="0.67893" />
            <inertia ixx="0.03" iyy="0.03" izz="0.03" ixy="0.0" ixz="0.0" iyz="0.0" />
        </inertial>
    </link>
    <link name="panda_leftfinger">
      <visual>
        <geometry>
          <mesh filename="package://franka_description/meshes/visual/finger.dae"/>
        </geometry>
      </visual>
      <collision>
        <geometry>
          <mesh filename="package://franka_description/meshes/collision/finger.stl"/>
        </geometry>
      </collision>
	<inertial>
            <mass value="0.01053" />
            <inertia ixx="0.03" iyy="0.03" izz="0.03" ixy="0.0" ixz="0.0" iyz="0.0" />
        </inertial>
    </link>
    <link name="panda_rightfinger">
      <visual>
        <origin xyz="0 0 0" rpy="0 0 3.14159"/>
        <geometry>
          <mesh filename="package://franka_description/meshes/visual/finger.dae"/>
        </geometry>
      </visual>
      <collision>
        <origin xyz="0 0 0" rpy="0 0 3.14159"/>
        <geometry>
          <mesh filename="package://franka_description/meshes/collision/finger.stl"/>
        </geometry>
      </collision>
	<inertial>
            <mass value="0.01053" />
            <inertia ixx="0.03" iyy="0.03" izz="0.03" ixy="0.0" ixz="0.0" iyz="0.0" />
        </inertial>
    </link>
  
  <gazebo reference="panda_leftfinger">
    <kp>1000000.0</kp>
    <kd>1.0</kd>
    <mu1>100000.0</mu1>
    <mu2>100000.0</mu2>
    <minDepth>0.001</minDepth>
  </gazebo>
  <gazebo reference="panda_rightfinger">
    <kp>1000000.0</kp>
    <kd>1.0</kd>
    <mu1>100000.0</mu1>
    <mu2>100000.0</mu2>
    <minDepth>0.001</minDepth>
  </gazebo>



    <joint name="panda_finger_joint1" type="fixed">
      <parent link="panda_hand"/>
      <child link="panda_leftfinger"/>
      <origin xyz="0 0 0.0584" rpy="0 0 0"/>
      <axis xyz="0 1 0"/>
      <!-- <limit effort="1000" lower="0.0" upper="0.04" velocity="0.1"/> -->
    </joint>
    <joint name="panda_finger_joint2" type="fixed">
      <parent link="panda_hand"/>
      <child link="panda_rightfinger"/>
      <origin xyz="0 0 0.0584" rpy="0 0 0"/>
      <axis xyz="0 -1 0"/>
      <!-- <limit effort="1000" lower="0.0" upper="0.04" velocity="0.1"/>
      <mimic joint="panda_finger_joint1" /> -->
    </joint>
    <link name="panda_ee_link"/>
    <joint name="panda_ee_joint" type="fixed">
      <parent link="panda_hand"/>
      <child link="panda_ee_link"/>
      <axis xyz="0 0 0"/>
    </joint>

    <transmission name="f_t_1">
      <type>transmission_interface/SimpleTransmission</type>
      <joint name="panda_finger_joint1">
	<hardwareInterface>hardware_interface/EffortJointInterface</hardwareInterface>
      </joint>
      <actuator name="motor_finger_1">
	<hardwareInterface>hardware_interface/EffortJointInterface</hardwareInterface>
	<mechanicalReduction>1</mechanicalReduction>
      </actuator>
    </transmission>

    <transmission name="f_t_2">
      <type>transmission_interface/SimpleTransmission</type>
      <joint name="panda_finger_joint2">
	<hardwareInterface>hardware_interface/EffortJointInterface</hardwareInterface>
      </joint>
      <actuator name="motor_finger_2">
	<hardwareInterface>hardware_interface/EffortJointInterface</hardwareInterface>
	<mechanicalReduction>1</mechanicalReduction>
      </actuator>
    </transmission>
  
<!-- **************** -->


    <!-- Transmissions of the robot arm - to be able to move each joint ============== -->
    <transmission name="tran1">
      <type>transmission_interface/SimpleTransmission</type>
      <joint name="panda_joint1">
	<hardwareInterface>hardware_interface/EffortJointInterface</hardwareInterface>
      </joint>
      <actuator name="motor1">
	<hardwareInterface>hardware_interface/EffortJointInterface</hardwareInterface>
	<mechanicalReduction>1</mechanicalReduction>
      </actuator>
    </transmission>

    <transmission name="tran2">
      <type>transmission_interface/SimpleTransmission</type>
      <joint name="panda_joint2">
	<hardwareInterface>hardware_interface/EffortJointInterface</hardwareInterface>
      </joint>
      <actuator name="motor2">
	<hardwareInterface>hardware_interface/EffortJointInterface</hardwareInterface>
	<mechanicalReduction>1</mechanicalReduction>
      </actuator>
    </transmission>

    <transmission name="tran3">
      <type>transmission_interface/SimpleTransmission</type>
      <joint name="panda_joint3">
	<hardwareInterface>hardware_interface/EffortJointInterface</hardwareInterface>
      </joint>
      <actuator name="motor3">
	<hardwareInterface>hardware_interface/EffortJointInterface</hardwareInterface>
	<mechanicalReduction>1</mechanicalReduction>
      </actuator>
    </transmission>

    <transmission name="tran4">
      <type>transmission_interface/SimpleTransmission</type>
      <joint name="panda_joint4">
	<hardwareInterface>hardware_interface/EffortJointInterface</hardwareInterface>
      </joint>
      <actuator name="motor4">
	<hardwareInterface>hardware_interface/EffortJointInterface</hardwareInterface>
	<mechanicalReduction>1</mechanicalReduction>
      </actuator>
    </transmission>

    <transmission name="tran5">
      <type>transmission_interface/SimpleTransmission</type>
      <joint name="panda_joint5">
	<hardwareInterface>hardware_interface/EffortJointInterface</hardwareInterface>
      </joint>
      <actuator name="motor5">
	<hardwareInterface>hardware_interface/EffortJointInterface</hardwareInterface>
	<mechanicalReduction>1</mechanicalReduction>
      </actuator>
    </transmission>

    <transmission name="tran6">
      <type>transmission_interface/SimpleTransmission</type>
      <joint name="panda_joint6">
	<hardwareInterface>hardware_interface/EffortJointInterface</hardwareInterface>
      </joint>
      <actuator name="motor6">
	<hardwareInterface>hardware_interface/EffortJointInterface</hardwareInterface>
	<mechanicalReduction>1</mechanicalReduction>
      </actuator>
    </transmission>

    <transmission name="tran7">
      <type>transmission_interface/SimpleTransmission</type>
      <joint name="panda_joint7">
	<hardwareInterface>hardware_interface/EffortJointInterface</hardwareInterface>
      </joint>
      <actuator name="motor7">
	<hardwareInterface>hardware_interface/EffortJointInterface</hardwareInterface>
	<mechanicalReduction>1</mechanicalReduction>
      </actuator>
    </transmission> 
  <!-- </xacro:macro> -->

  <!-- Gazebo control plugin -->
  <gazebo>
    <plugin name="gazebo_ros_control" filename="libgazebo_ros_control.so">
      <robotNamespace>/panda</robotNamespace>
      <robotSimType>gazebo_ros_control/DefaultRobotHWSim</robotSimType>
    </plugin>
  </gazebo>

</robot>
