<?xml version="1.0"?>
<robot name="mug">
  <link name="world" />

  <link name="mug">
    <visual>
      <geometry>
	<mesh filename="package://ycb_models/mesh/mug.dae" />
      </geometry>
    </visual>
    <collision>
      <geometry>
	<mesh filename="package://ycb_models/mesh/mug.dae" />
      </geometry>
    </collision>
    <!-- PLACEHOLDER VALUES -->
    <inertial>
      <origin xyz="-0.0188777 0.0268737 -0.016566" rpy="0 0 0" />
      <mass value="0.01" />
      <inertia ixx="7.151e-04" ixy="0" ixz="0"
	       iyy="7.151e-05" iyz="0"
	       izz="8.182e-05" />
    </inertial>
  </link>

  <joint name="table_mug" type="floating">
    <origin rpy="0 0 0" xyz="0 0 0" />
    <parent link="world" />
    <child link="mug" />
  </joint>

  <!-- Gazebo-related details -->
  <gazebo reference="mug">
    <dampingFactor>0.005</dampingFactor>
    <kp>1000000.0</kp>
    <kd>1.0</kd>
    <mu1>1.0</mu1>
    <mu2>1.0</mu2>
    <minDepth>0.001</minDepth>
  </gazebo>

</robot>
