<?xml version="1.0"?>
<robot name="mug">
  <link name="world" />

  <link name="mug">
    <visual>
      <geometry>
	<mesh filename="package://ycb_models/mesh/mug/textured.dae" />
      </geometry>
    </visual>
    <collision>
      <geometry>
	<mesh filename="package://ycb_models/mesh/mug/textured.dae" />
      </geometry>
    </collision>
    <!-- PLACEHOLDER VALUES -->
    <inertial>
      <origin xyz="-0.0188586 0.016573 0.0268989" rpy="0 0 0" />
      <mass value="0.01" />
      <inertia ixx="0.011903e-5" ixy="0.000075e-5" ixz="-0.00034e-5"
	       iyy="0.013529e-05" iyz="-0.000294e-5"
	       izz="0.017241e-05" />
    </inertial>
  </link>

  <joint name="table_mug" type="floating">
    <origin rpy="0 0 0" xyz="0 0 0" />
    <parent link="world" />
    <child link="mug" />
  </joint>

  <!-- Gazebo-related details -->
  <gazebo reference="mug">
    <dampingFactor>0.005</dampingFactor>
    <kp>1000000.0</kp>
    <kd>1.0</kd>
    <mu1>10000.0</mu1>
    <mu2>10000.0</mu2>
    <!-- <minDepth>0.0005</minDepth> -->
    <maxVel>0.05</maxVel>
  </gazebo>

</robot>
